<?xml version="1.0"?>
<robot xmlns:xacro="http://www.ros.org/wiki/xacro" name="rethink_electric_gripper">
  <xacro:property name="pi" value="3.1415926535897931" />
  <xacro:macro name="rethink_electric_gripper" params="side gripper_side  r_finger r_finger_slot add_r_finger_tip r_finger_tip l_finger l_finger_slot add_l_finger_tip l_finger_tip">

    <!-- Base of end effector -->
    <link name="${side}_gripper_electric_base">
      <gravity>0</gravity>
      <visual>
        <origin rpy="${-pi/2} ${pi} 0" xyz="0 0 0"/>
        <geometry>
          <mesh filename="package://baxter_description/meshes/electric_gripper/electric_gripper_base.DAE"/>
        </geometry>
      </visual>
      <collision>
        <origin rpy="${-pi/2} ${pi} 0" xyz="0.0 0.0 0"/>
        <geometry>
          <cylinder length="0.1" radius="0.029"/>
        </geometry>
        <material name="darkred">
          <color rgba=".5 .1 .1 1"/>
        </material>
      </collision>
      <inertial>
        <origin rpy="${-pi/2} ${pi} 0" xyz="0.0 0.0 0.0"/>
        <mass value="0.3"/>
        <inertia ixx="2e-08" ixy="0" ixz="0" iyy="3e-08" iyz="0" izz="2e-08"/>
      </inertial>
    </link>

    <!-- Left finger link -->
    <xacro:include filename="$(find baxter_description)/urdf/${l_finger}.xacro" />
    <xacro:finger_xacro gripper_side="${side}" finger_side="l" reflect="1" finger_tip="${l_finger_tip}" add_finger_tip="${add_l_finger_tip}"/>

    <!-- Right finger link -->
    <xacro:include filename="$(find baxter_description)/urdf/${r_finger}.xacro" />
    <xacro:finger_xacro gripper_side="${side}" finger_side="r" reflect="-1" finger_tip="${r_finger_tip}" add_finger_tip="${add_r_finger_tip}"/>

    <!-- Electric Gripper Base -->
    <joint name="${gripper_side}_gripper_electric_base_joint" type="fixed">
      <origin rpy="0 0 0" xyz="0 0 0.025"/>
      <parent link="${side}_gripper_base"/>
      <child link="${side}_gripper_electric_base"/>
    </joint>

    <!-- Left finger -->
    <joint name="${gripper_side}_gripper_l_finger_joint" type="prismatic">
      <origin rpy="0 0 0" xyz="0.0 ${(l_finger_slot-1)*0.0095-0.011} 0.017"/>
      <axis xyz="0 1 0"/>
      <parent link="${side}_gripper_electric_base"/>
      <child link="${side}_gripper_l_finger"/>
      <limit effort="20.0" lower="${(l_finger_slot-1)*0.0095-0.011 + 0.020833}" upper="${(l_finger_slot-1)*0.0095-0.011}" velocity="5.0"/>
      <dynamics damping="0.7" friction="0.0"/>
    </joint>

    <!-- Right finger -->
    <joint name="${gripper_side}_gripper_r_finger_joint" type="prismatic">
      <origin rpy="0 0 0" xyz="0.0 ${(r_finger_slot-1)*-0.0095+0.011} 0.017"/>
      <axis xyz="0 1 0"/>
      <parent link="${side}_gripper_electric_base"/>
      <child link="${side}_gripper_r_finger"/>
      <limit effort="20.0" lower="${(r_finger_slot-1)*-0.0095+0.011 - 0.020833}" upper="${(r_finger_slot-1)*-0.0095+0.011}" velocity="5.0"/>
      <dynamics damping="0.7" friction="0.0"/>
    </joint>

    <transmission name="gripper_${side}1">
      <type>transmission_interface/SimpleTransmission</type>
      <joint name="${gripper_side}_gripper_r_finger_joint">
        <hardwareInterface>EffortJointInterface</hardwareInterface>
      </joint>
      <actuator name="gripper_${gripper_side}1_motor1">
        <hardwareInterface>EffortJointInterface</hardwareInterface>
        <mechanicalReduction>1</mechanicalReduction>
      </actuator>
    </transmission>
    <transmission name="gripper_${side}2">
      <type>transmission_interface/SimpleTransmission</type>
      <joint name="${gripper_side}_gripper_l_finger_joint">
        <hardwareInterface>EffortJointInterface</hardwareInterface>
      </joint>
      <actuator name="gripper_${gripper_side}1_motor2">
        <hardwareInterface>EffortJointInterface</hardwareInterface>
        <mechanicalReduction>1</mechanicalReduction>
      </actuator>
    </transmission>

    <gazebo reference="${gripper_side}_gripper_r_finger_joint">
      <implicitSpringDamper>1</implicitSpringDamper>
    </gazebo>
    <gazebo reference="${gripper_side}_gripper_l_finger_joint">
      <implicitSpringDamper>1</implicitSpringDamper>
    </gazebo>

  </xacro:macro>
</robot>
